Fatal Python error: Segmentation fault

Current thread 0x00002b661c600740 (most recent call first):
  File "<__array_function__ internals>", line 5 in dot
  File "/opt/conda/lib/python3.8/site-packages/nibabel/orientations.py", line 70 in io_orientation
  File "/opt/conda/lib/python3.8/site-packages/nibabel/funcs.py", line 205 in as_closest_canonical
  File "/opt/conda/lib/python3.8/site-packages/mriqc/viz/utils.py", line 283 in plot_mosaic
  File "/opt/conda/lib/python3.8/site-packages/mriqc/interfaces/viz.py", line 153 in _run_interface
  File "/opt/conda/lib/python3.8/site-packages/nipype/interfaces/base/core.py", line 428 in run
  File "/opt/conda/lib/python3.8/site-packages/nipype/pipeline/engine/nodes.py", line 741 in _run_command
  File "/opt/conda/lib/python3.8/site-packages/nipype/pipeline/engine/nodes.py", line 635 in _run_interface
  File "/opt/conda/lib/python3.8/site-packages/nipype/pipeline/engine/nodes.py", line 516 in run
  File "/opt/conda/lib/python3.8/site-packages/nipype/pipeline/plugins/multiproc.py", line 67 in run_node
  File "/opt/conda/lib/python3.8/concurrent/futures/process.py", line 239 in _process_worker
  File "/opt/conda/lib/python3.8/multiprocessing/process.py", line 108 in run
  File "/opt/conda/lib/python3.8/multiprocessing/process.py", line 315 in _bootstrap
  File "/opt/conda/lib/python3.8/multiprocessing/spawn.py", line 129 in _main
  File "/opt/conda/lib/python3.8/multiprocessing/forkserver.py", line 319 in _serve_one
  File "/opt/conda/lib/python3.8/multiprocessing/forkserver.py", line 280 in main
  File "<string>", line 1 in <module>
exception calling callback for <Future at 0x2b8bc79d9ee0 state=finished raised BrokenProcessPool>
Traceback (most recent call last):
  File "/opt/conda/lib/python3.8/concurrent/futures/_base.py", line 328, in _invoke_callbacks
    callback(self)
  File "/opt/conda/lib/python3.8/site-packages/nipype/pipeline/plugins/multiproc.py", line 159, in _async_callback
    result = args.result()
  File "/opt/conda/lib/python3.8/concurrent/futures/_base.py", line 432, in result
    return self.__get_result()
  File "/opt/conda/lib/python3.8/concurrent/futures/_base.py", line 388, in __get_result
    raise self._exception
concurrent.futures.process.BrokenProcessPool: A process in the process pool was terminated abruptly while the future was running or pending.
exception calling callback for <Future at 0x2b8b9fb3fdf0 state=finished raised BrokenProcessPool>
Traceback (most recent call last):
  File "/opt/conda/lib/python3.8/concurrent/futures/_base.py", line 328, in _invoke_callbacks
    callback(self)
  File "/opt/conda/lib/python3.8/site-packages/nipype/pipeline/plugins/multiproc.py", line 159, in _async_callback
    result = args.result()
  File "/opt/conda/lib/python3.8/concurrent/futures/_base.py", line 432, in result
    return self.__get_result()
  File "/opt/conda/lib/python3.8/concurrent/futures/_base.py", line 388, in __get_result
    raise self._exception
  File "/opt/conda/lib/python3.8/concurrent/futures/_base.py", line 328, in _invoke_callbacks
    callback(self)
  File "/opt/conda/lib/python3.8/site-packages/nipype/pipeline/plugins/multiproc.py", line 159, in _async_callback
    result = args.result()
  File "/opt/conda/lib/python3.8/concurrent/futures/_base.py", line 432, in result
    return self.__get_result()
  File "/opt/conda/lib/python3.8/concurrent/futures/_base.py", line 388, in __get_result
    raise self._exception
concurrent.futures.process.BrokenProcessPool: A process in the process pool was terminated abruptly while the future was running or pending.
exception calling callback for <Future at 0x2b8b9fb3faf0 state=finished raised BrokenProcessPool>
Traceback (most recent call last):
  File "/opt/conda/lib/python3.8/concurrent/futures/_base.py", line 328, in _invoke_callbacks
    callback(self)
  File "/opt/conda/lib/python3.8/site-packages/nipype/pipeline/plugins/multiproc.py", line 159, in _async_callback
    result = args.result()
  File "/opt/conda/lib/python3.8/concurrent/futures/_base.py", line 432, in result
    return self.__get_result()
  File "/opt/conda/lib/python3.8/concurrent/futures/_base.py", line 388, in __get_result
    raise self._exception
  File "/opt/conda/lib/python3.8/concurrent/futures/_base.py", line 328, in _invoke_callbacks
    callback(self)
  File "/opt/conda/lib/python3.8/site-packages/nipype/pipeline/plugins/multiproc.py", line 159, in _async_callback
    result = args.result()
  File "/opt/conda/lib/python3.8/concurrent/futures/_base.py", line 432, in result
    return self.__get_result()
  File "/opt/conda/lib/python3.8/concurrent/futures/_base.py", line 388, in __get_result
    raise self._exception
  File "/opt/conda/lib/python3.8/concurrent/futures/_base.py", line 328, in _invoke_callbacks
    callback(self)
  File "/opt/conda/lib/python3.8/site-packages/nipype/pipeline/plugins/multiproc.py", line 159, in _async_callback
    result = args.result()
  File "/opt/conda/lib/python3.8/concurrent/futures/_base.py", line 432, in result
    return self.__get_result()
  File "/opt/conda/lib/python3.8/concurrent/futures/_base.py", line 388, in __get_result
    raise self._exception
concurrent.futures.process.BrokenProcessPool: A process in the process pool was terminated abruptly while the future was running or pending.
exception calling callback for <Future at 0x2b8b9fb3f100 state=finished raised BrokenProcessPool>
Traceback (most recent call last):
  File "/opt/conda/lib/python3.8/concurrent/futures/_base.py", line 328, in _invoke_callbacks
    callback(self)
  File "/opt/conda/lib/python3.8/site-packages/nipype/pipeline/plugins/multiproc.py", line 159, in _async_callback
    result = args.result()
  File "/opt/conda/lib/python3.8/concurrent/futures/_base.py", line 432, in result
    return self.__get_result()
  File "/opt/conda/lib/python3.8/concurrent/futures/_base.py", line 388, in __get_result
    raise self._exception
  File "/opt/conda/lib/python3.8/concurrent/futures/_base.py", line 328, in _invoke_callbacks
    callback(self)
  File "/opt/conda/lib/python3.8/site-packages/nipype/pipeline/plugins/multiproc.py", line 159, in _async_callback
    result = args.result()
  File "/opt/conda/lib/python3.8/concurrent/futures/_base.py", line 432, in result
    return self.__get_result()
  File "/opt/conda/lib/python3.8/concurrent/futures/_base.py", line 388, in __get_result
    raise self._exception
  File "/opt/conda/lib/python3.8/concurrent/futures/_base.py", line 328, in _invoke_callbacks
    callback(self)
  File "/opt/conda/lib/python3.8/site-packages/nipype/pipeline/plugins/multiproc.py", line 159, in _async_callback
    result = args.result()
  File "/opt/conda/lib/python3.8/concurrent/futures/_base.py", line 432, in result
    return self.__get_result()
  File "/opt/conda/lib/python3.8/concurrent/futures/_base.py", line 388, in __get_result
    raise self._exception
  File "/opt/conda/lib/python3.8/concurrent/futures/_base.py", line 328, in _invoke_callbacks
    callback(self)
  File "/opt/conda/lib/python3.8/site-packages/nipype/pipeline/plugins/multiproc.py", line 159, in _async_callback
    result = args.result()
  File "/opt/conda/lib/python3.8/concurrent/futures/_base.py", line 432, in result
    return self.__get_result()
  File "/opt/conda/lib/python3.8/concurrent/futures/_base.py", line 388, in __get_result
    raise self._exception
concurrent.futures.process.BrokenProcessPool: A process in the process pool was terminated abruptly while the future was running or pending.
exception calling callback for <Future at 0x2b8b9fb3fb20 state=finished raised BrokenProcessPool>
Traceback (most recent call last):
  File "/opt/conda/lib/python3.8/concurrent/futures/_base.py", line 328, in _invoke_callbacks
    callback(self)
  File "/opt/conda/lib/python3.8/site-packages/nipype/pipeline/plugins/multiproc.py", line 159, in _async_callback
    result = args.result()
  File "/opt/conda/lib/python3.8/concurrent/futures/_base.py", line 432, in result
    return self.__get_result()
  File "/opt/conda/lib/python3.8/concurrent/futures/_base.py", line 388, in __get_result
    raise self._exception
  File "/opt/conda/lib/python3.8/concurrent/futures/_base.py", line 328, in _invoke_callbacks
    callback(self)
  File "/opt/conda/lib/python3.8/site-packages/nipype/pipeline/plugins/multiproc.py", line 159, in _async_callback
    result = args.result()
  File "/opt/conda/lib/python3.8/concurrent/futures/_base.py", line 432, in result
    return self.__get_result()
  File "/opt/conda/lib/python3.8/concurrent/futures/_base.py", line 388, in __get_result
    raise self._exception
  File "/opt/conda/lib/python3.8/concurrent/futures/_base.py", line 328, in _invoke_callbacks
    callback(self)
  File "/opt/conda/lib/python3.8/site-packages/nipype/pipeline/plugins/multiproc.py", line 159, in _async_callback
    result = args.result()
  File "/opt/conda/lib/python3.8/concurrent/futures/_base.py", line 432, in result
    return self.__get_result()
  File "/opt/conda/lib/python3.8/concurrent/futures/_base.py", line 388, in __get_result
    raise self._exception
  File "/opt/conda/lib/python3.8/concurrent/futures/_base.py", line 328, in _invoke_callbacks
    callback(self)
  File "/opt/conda/lib/python3.8/site-packages/nipype/pipeline/plugins/multiproc.py", line 159, in _async_callback
    result = args.result()
  File "/opt/conda/lib/python3.8/concurrent/futures/_base.py", line 432, in result
    return self.__get_result()
  File "/opt/conda/lib/python3.8/concurrent/futures/_base.py", line 388, in __get_result
    raise self._exception
  File "/opt/conda/lib/python3.8/concurrent/futures/_base.py", line 328, in _invoke_callbacks
    callback(self)
  File "/opt/conda/lib/python3.8/site-packages/nipype/pipeline/plugins/multiproc.py", line 159, in _async_callback
    result = args.result()
  File "/opt/conda/lib/python3.8/concurrent/futures/_base.py", line 432, in result
    return self.__get_result()
  File "/opt/conda/lib/python3.8/concurrent/futures/_base.py", line 388, in __get_result
    raise self._exception
concurrent.futures.process.BrokenProcessPool: A process in the process pool was terminated abruptly while the future was running or pending.
exception calling callback for <Future at 0x2b8b9fb3ff70 state=finished raised BrokenProcessPool>
Traceback (most recent call last):
  File "/opt/conda/lib/python3.8/concurrent/futures/_base.py", line 328, in _invoke_callbacks
    callback(self)
  File "/opt/conda/lib/python3.8/site-packages/nipype/pipeline/plugins/multiproc.py", line 159, in _async_callback
    result = args.result()
  File "/opt/conda/lib/python3.8/concurrent/futures/_base.py", line 432, in result
    return self.__get_result()
  File "/opt/conda/lib/python3.8/concurrent/futures/_base.py", line 388, in __get_result
    raise self._exception
  File "/opt/conda/lib/python3.8/concurrent/futures/_base.py", line 328, in _invoke_callbacks
    callback(self)
  File "/opt/conda/lib/python3.8/site-packages/nipype/pipeline/plugins/multiproc.py", line 159, in _async_callback
    result = args.result()
  File "/opt/conda/lib/python3.8/concurrent/futures/_base.py", line 432, in result
    return self.__get_result()
  File "/opt/conda/lib/python3.8/concurrent/futures/_base.py", line 388, in __get_result
    raise self._exception
  File "/opt/conda/lib/python3.8/concurrent/futures/_base.py", line 328, in _invoke_callbacks
    callback(self)
  File "/opt/conda/lib/python3.8/site-packages/nipype/pipeline/plugins/multiproc.py", line 159, in _async_callback
    result = args.result()
  File "/opt/conda/lib/python3.8/concurrent/futures/_base.py", line 432, in result
    return self.__get_result()
  File "/opt/conda/lib/python3.8/concurrent/futures/_base.py", line 388, in __get_result
    raise self._exception
  File "/opt/conda/lib/python3.8/concurrent/futures/_base.py", line 328, in _invoke_callbacks
    callback(self)
  File "/opt/conda/lib/python3.8/site-packages/nipype/pipeline/plugins/multiproc.py", line 159, in _async_callback
    result = args.result()
  File "/opt/conda/lib/python3.8/concurrent/futures/_base.py", line 432, in result
    return self.__get_result()
  File "/opt/conda/lib/python3.8/concurrent/futures/_base.py", line 388, in __get_result
    raise self._exception
  File "/opt/conda/lib/python3.8/concurrent/futures/_base.py", line 328, in _invoke_callbacks
    callback(self)
  File "/opt/conda/lib/python3.8/site-packages/nipype/pipeline/plugins/multiproc.py", line 159, in _async_callback
    result = args.result()
  File "/opt/conda/lib/python3.8/concurrent/futures/_base.py", line 432, in result
    return self.__get_result()
  File "/opt/conda/lib/python3.8/concurrent/futures/_base.py", line 388, in __get_result
    raise self._exception
  File "/opt/conda/lib/python3.8/concurrent/futures/_base.py", line 328, in _invoke_callbacks
    callback(self)
  File "/opt/conda/lib/python3.8/site-packages/nipype/pipeline/plugins/multiproc.py", line 159, in _async_callback
    result = args.result()
  File "/opt/conda/lib/python3.8/concurrent/futures/_base.py", line 432, in result
    return self.__get_result()
  File "/opt/conda/lib/python3.8/concurrent/futures/_base.py", line 388, in __get_result
    raise self._exception
concurrent.futures.process.BrokenProcessPool: A process in the process pool was terminated abruptly while the future was running or pending.
exception calling callback for <Future at 0x2b8ba17a5a00 state=finished raised BrokenProcessPool>
Traceback (most recent call last):
  File "/opt/conda/lib/python3.8/concurrent/futures/_base.py", line 328, in _invoke_callbacks
    callback(self)
  File "/opt/conda/lib/python3.8/site-packages/nipype/pipeline/plugins/multiproc.py", line 159, in _async_callback
    result = args.result()
  File "/opt/conda/lib/python3.8/concurrent/futures/_base.py", line 432, in result
    return self.__get_result()
  File "/opt/conda/lib/python3.8/concurrent/futures/_base.py", line 388, in __get_result
    raise self._exception
  File "/opt/conda/lib/python3.8/concurrent/futures/_base.py", line 328, in _invoke_callbacks
    callback(self)
  File "/opt/conda/lib/python3.8/site-packages/nipype/pipeline/plugins/multiproc.py", line 159, in _async_callback
    result = args.result()
  File "/opt/conda/lib/python3.8/concurrent/futures/_base.py", line 432, in result
    return self.__get_result()
  File "/opt/conda/lib/python3.8/concurrent/futures/_base.py", line 388, in __get_result
    raise self._exception
  File "/opt/conda/lib/python3.8/concurrent/futures/_base.py", line 328, in _invoke_callbacks
    callback(self)
  File "/opt/conda/lib/python3.8/site-packages/nipype/pipeline/plugins/multiproc.py", line 159, in _async_callback
    result = args.result()
  File "/opt/conda/lib/python3.8/concurrent/futures/_base.py", line 432, in result
    return self.__get_result()
  File "/opt/conda/lib/python3.8/concurrent/futures/_base.py", line 388, in __get_result
    raise self._exception
  File "/opt/conda/lib/python3.8/concurrent/futures/_base.py", line 328, in _invoke_callbacks
    callback(self)
  File "/opt/conda/lib/python3.8/site-packages/nipype/pipeline/plugins/multiproc.py", line 159, in _async_callback
    result = args.result()
  File "/opt/conda/lib/python3.8/concurrent/futures/_base.py", line 432, in result
    return self.__get_result()
  File "/opt/conda/lib/python3.8/concurrent/futures/_base.py", line 388, in __get_result
    raise self._exception
  File "/opt/conda/lib/python3.8/concurrent/futures/_base.py", line 328, in _invoke_callbacks
    callback(self)
  File "/opt/conda/lib/python3.8/site-packages/nipype/pipeline/plugins/multiproc.py", line 159, in _async_callback
    result = args.result()
  File "/opt/conda/lib/python3.8/concurrent/futures/_base.py", line 432, in result
    return self.__get_result()
  File "/opt/conda/lib/python3.8/concurrent/futures/_base.py", line 388, in __get_result
    raise self._exception
  File "/opt/conda/lib/python3.8/concurrent/futures/_base.py", line 328, in _invoke_callbacks
    callback(self)
  File "/opt/conda/lib/python3.8/site-packages/nipype/pipeline/plugins/multiproc.py", line 159, in _async_callback
    result = args.result()
  File "/opt/conda/lib/python3.8/concurrent/futures/_base.py", line 432, in result
    return self.__get_result()
  File "/opt/conda/lib/python3.8/concurrent/futures/_base.py", line 388, in __get_result
    raise self._exception
  File "/opt/conda/lib/python3.8/concurrent/futures/_base.py", line 328, in _invoke_callbacks
    callback(self)
  File "/opt/conda/lib/python3.8/site-packages/nipype/pipeline/plugins/multiproc.py", line 159, in _async_callback
    result = args.result()
  File "/opt/conda/lib/python3.8/concurrent/futures/_base.py", line 432, in result
    return self.__get_result()
  File "/opt/conda/lib/python3.8/concurrent/futures/_base.py", line 388, in __get_result
    raise self._exception
concurrent.futures.process.BrokenProcessPool: A process in the process pool was terminated abruptly while the future was running or pending.
exception calling callback for <Future at 0x2b8ba17a5670 state=finished raised BrokenProcessPool>
Traceback (most recent call last):
  File "/opt/conda/lib/python3.8/concurrent/futures/_base.py", line 328, in _invoke_callbacks
    callback(self)
  File "/opt/conda/lib/python3.8/site-packages/nipype/pipeline/plugins/multiproc.py", line 159, in _async_callback
    result = args.result()
  File "/opt/conda/lib/python3.8/concurrent/futures/_base.py", line 432, in result
    return self.__get_result()
  File "/opt/conda/lib/python3.8/concurrent/futures/_base.py", line 388, in __get_result
    raise self._exception
  File "/opt/conda/lib/python3.8/concurrent/futures/_base.py", line 328, in _invoke_callbacks
    callback(self)
  File "/opt/conda/lib/python3.8/site-packages/nipype/pipeline/plugins/multiproc.py", line 159, in _async_callback
    result = args.result()
  File "/opt/conda/lib/python3.8/concurrent/futures/_base.py", line 432, in result
    return self.__get_result()
  File "/opt/conda/lib/python3.8/concurrent/futures/_base.py", line 388, in __get_result
    raise self._exception
  File "/opt/conda/lib/python3.8/concurrent/futures/_base.py", line 328, in _invoke_callbacks
    callback(self)
  File "/opt/conda/lib/python3.8/site-packages/nipype/pipeline/plugins/multiproc.py", line 159, in _async_callback
    result = args.result()
  File "/opt/conda/lib/python3.8/concurrent/futures/_base.py", line 432, in result
    return self.__get_result()
  File "/opt/conda/lib/python3.8/concurrent/futures/_base.py", line 388, in __get_result
    raise self._exception
  File "/opt/conda/lib/python3.8/concurrent/futures/_base.py", line 328, in _invoke_callbacks
    callback(self)
  File "/opt/conda/lib/python3.8/site-packages/nipype/pipeline/plugins/multiproc.py", line 159, in _async_callback
    result = args.result()
  File "/opt/conda/lib/python3.8/concurrent/futures/_base.py", line 432, in result
    return self.__get_result()
  File "/opt/conda/lib/python3.8/concurrent/futures/_base.py", line 388, in __get_result
    raise self._exception
  File "/opt/conda/lib/python3.8/concurrent/futures/_base.py", line 328, in _invoke_callbacks
    callback(self)
  File "/opt/conda/lib/python3.8/site-packages/nipype/pipeline/plugins/multiproc.py", line 159, in _async_callback
    result = args.result()
  File "/opt/conda/lib/python3.8/concurrent/futures/_base.py", line 432, in result
    return self.__get_result()
  File "/opt/conda/lib/python3.8/concurrent/futures/_base.py", line 388, in __get_result
    raise self._exception
  File "/opt/conda/lib/python3.8/concurrent/futures/_base.py", line 328, in _invoke_callbacks
    callback(self)
  File "/opt/conda/lib/python3.8/site-packages/nipype/pipeline/plugins/multiproc.py", line 159, in _async_callback
    result = args.result()
  File "/opt/conda/lib/python3.8/concurrent/futures/_base.py", line 432, in result
    return self.__get_result()
  File "/opt/conda/lib/python3.8/concurrent/futures/_base.py", line 388, in __get_result
    raise self._exception
  File "/opt/conda/lib/python3.8/concurrent/futures/_base.py", line 328, in _invoke_callbacks
    callback(self)
  File "/opt/conda/lib/python3.8/site-packages/nipype/pipeline/plugins/multiproc.py", line 159, in _async_callback
    result = args.result()
  File "/opt/conda/lib/python3.8/concurrent/futures/_base.py", line 432, in result
    return self.__get_result()
  File "/opt/conda/lib/python3.8/concurrent/futures/_base.py", line 388, in __get_result
    raise self._exception
  File "/opt/conda/lib/python3.8/concurrent/futures/_base.py", line 328, in _invoke_callbacks
    callback(self)
  File "/opt/conda/lib/python3.8/site-packages/nipype/pipeline/plugins/multiproc.py", line 159, in _async_callback
    result = args.result()
  File "/opt/conda/lib/python3.8/concurrent/futures/_base.py", line 432, in result
    return self.__get_result()
  File "/opt/conda/lib/python3.8/concurrent/futures/_base.py", line 388, in __get_result
    raise self._exception
concurrent.futures.process.BrokenProcessPool: A process in the process pool was terminated abruptly while the future was running or pending.
exception calling callback for <Future at 0x2b8ba17a57c0 state=finished raised BrokenProcessPool>
Traceback (most recent call last):
  File "/opt/conda/lib/python3.8/concurrent/futures/_base.py", line 328, in _invoke_callbacks
    callback(self)
  File "/opt/conda/lib/python3.8/site-packages/nipype/pipeline/plugins/multiproc.py", line 159, in _async_callback
    result = args.result()
  File "/opt/conda/lib/python3.8/concurrent/futures/_base.py", line 432, in result
    return self.__get_result()
  File "/opt/conda/lib/python3.8/concurrent/futures/_base.py", line 388, in __get_result
    raise self._exception
  File "/opt/conda/lib/python3.8/concurrent/futures/_base.py", line 328, in _invoke_callbacks
    callback(self)
  File "/opt/conda/lib/python3.8/site-packages/nipype/pipeline/plugins/multiproc.py", line 159, in _async_callback
    result = args.result()
  File "/opt/conda/lib/python3.8/concurrent/futures/_base.py", line 432, in result
    return self.__get_result()
  File "/opt/conda/lib/python3.8/concurrent/futures/_base.py", line 388, in __get_result
    raise self._exception
  File "/opt/conda/lib/python3.8/concurrent/futures/_base.py", line 328, in _invoke_callbacks
    callback(self)
  File "/opt/conda/lib/python3.8/site-packages/nipype/pipeline/plugins/multiproc.py", line 159, in _async_callback
    result = args.result()
  File "/opt/conda/lib/python3.8/concurrent/futures/_base.py", line 432, in result
    return self.__get_result()
  File "/opt/conda/lib/python3.8/concurrent/futures/_base.py", line 388, in __get_result
    raise self._exception
  File "/opt/conda/lib/python3.8/concurrent/futures/_base.py", line 328, in _invoke_callbacks
    callback(self)
  File "/opt/conda/lib/python3.8/site-packages/nipype/pipeline/plugins/multiproc.py", line 159, in _async_callback
    result = args.result()
  File "/opt/conda/lib/python3.8/concurrent/futures/_base.py", line 432, in result
    return self.__get_result()
  File "/opt/conda/lib/python3.8/concurrent/futures/_base.py", line 388, in __get_result
    raise self._exception
  File "/opt/conda/lib/python3.8/concurrent/futures/_base.py", line 328, in _invoke_callbacks
    callback(self)
  File "/opt/conda/lib/python3.8/site-packages/nipype/pipeline/plugins/multiproc.py", line 159, in _async_callback
    result = args.result()
  File "/opt/conda/lib/python3.8/concurrent/futures/_base.py", line 432, in result
    return self.__get_result()
  File "/opt/conda/lib/python3.8/concurrent/futures/_base.py", line 388, in __get_result
    raise self._exception
  File "/opt/conda/lib/python3.8/concurrent/futures/_base.py", line 328, in _invoke_callbacks
    callback(self)
  File "/opt/conda/lib/python3.8/site-packages/nipype/pipeline/plugins/multiproc.py", line 159, in _async_callback
    result = args.result()
  File "/opt/conda/lib/python3.8/concurrent/futures/_base.py", line 432, in result
    return self.__get_result()
  File "/opt/conda/lib/python3.8/concurrent/futures/_base.py", line 388, in __get_result
    raise self._exception
  File "/opt/conda/lib/python3.8/concurrent/futures/_base.py", line 328, in _invoke_callbacks
    callback(self)
  File "/opt/conda/lib/python3.8/site-packages/nipype/pipeline/plugins/multiproc.py", line 159, in _async_callback
    result = args.result()
  File "/opt/conda/lib/python3.8/concurrent/futures/_base.py", line 432, in result
    return self.__get_result()
  File "/opt/conda/lib/python3.8/concurrent/futures/_base.py", line 388, in __get_result
    raise self._exception
  File "/opt/conda/lib/python3.8/concurrent/futures/_base.py", line 328, in _invoke_callbacks
    callback(self)
  File "/opt/conda/lib/python3.8/site-packages/nipype/pipeline/plugins/multiproc.py", line 159, in _async_callback
    result = args.result()
  File "/opt/conda/lib/python3.8/concurrent/futures/_base.py", line 432, in result
    return self.__get_result()
  File "/opt/conda/lib/python3.8/concurrent/futures/_base.py", line 388, in __get_result
    raise self._exception
  File "/opt/conda/lib/python3.8/concurrent/futures/_base.py", line 328, in _invoke_callbacks
    callback(self)
  File "/opt/conda/lib/python3.8/site-packages/nipype/pipeline/plugins/multiproc.py", line 159, in _async_callback
    result = args.result()
  File "/opt/conda/lib/python3.8/concurrent/futures/_base.py", line 432, in result
    return self.__get_result()
  File "/opt/conda/lib/python3.8/concurrent/futures/_base.py", line 388, in __get_result
    raise self._exception
concurrent.futures.process.BrokenProcessPool: A process in the process pool was terminated abruptly while the future was running or pending.
exception calling callback for <Future at 0x2b8b9fb3fb50 state=finished raised BrokenProcessPool>
Traceback (most recent call last):
  File "/opt/conda/lib/python3.8/concurrent/futures/_base.py", line 328, in _invoke_callbacks
    callback(self)
  File "/opt/conda/lib/python3.8/site-packages/nipype/pipeline/plugins/multiproc.py", line 159, in _async_callback
    result = args.result()
  File "/opt/conda/lib/python3.8/concurrent/futures/_base.py", line 432, in result
    return self.__get_result()
  File "/opt/conda/lib/python3.8/concurrent/futures/_base.py", line 388, in __get_result
    raise self._exception
  File "/opt/conda/lib/python3.8/concurrent/futures/_base.py", line 328, in _invoke_callbacks
    callback(self)
  File "/opt/conda/lib/python3.8/site-packages/nipype/pipeline/plugins/multiproc.py", line 159, in _async_callback
    result = args.result()
  File "/opt/conda/lib/python3.8/concurrent/futures/_base.py", line 432, in result
    return self.__get_result()
  File "/opt/conda/lib/python3.8/concurrent/futures/_base.py", line 388, in __get_result
    raise self._exception
  File "/opt/conda/lib/python3.8/concurrent/futures/_base.py", line 328, in _invoke_callbacks
    callback(self)
  File "/opt/conda/lib/python3.8/site-packages/nipype/pipeline/plugins/multiproc.py", line 159, in _async_callback
    result = args.result()
  File "/opt/conda/lib/python3.8/concurrent/futures/_base.py", line 432, in result
    return self.__get_result()
  File "/opt/conda/lib/python3.8/concurrent/futures/_base.py", line 388, in __get_result
    raise self._exception
  File "/opt/conda/lib/python3.8/concurrent/futures/_base.py", line 328, in _invoke_callbacks
    callback(self)
  File "/opt/conda/lib/python3.8/site-packages/nipype/pipeline/plugins/multiproc.py", line 159, in _async_callback
    result = args.result()
  File "/opt/conda/lib/python3.8/concurrent/futures/_base.py", line 432, in result
    return self.__get_result()
  File "/opt/conda/lib/python3.8/concurrent/futures/_base.py", line 388, in __get_result
    raise self._exception
  File "/opt/conda/lib/python3.8/concurrent/futures/_base.py", line 328, in _invoke_callbacks
    callback(self)
  File "/opt/conda/lib/python3.8/site-packages/nipype/pipeline/plugins/multiproc.py", line 159, in _async_callback
    result = args.result()
  File "/opt/conda/lib/python3.8/concurrent/futures/_base.py", line 432, in result
    return self.__get_result()
  File "/opt/conda/lib/python3.8/concurrent/futures/_base.py", line 388, in __get_result
    raise self._exception
  File "/opt/conda/lib/python3.8/concurrent/futures/_base.py", line 328, in _invoke_callbacks
    callback(self)
  File "/opt/conda/lib/python3.8/site-packages/nipype/pipeline/plugins/multiproc.py", line 159, in _async_callback
    result = args.result()
  File "/opt/conda/lib/python3.8/concurrent/futures/_base.py", line 432, in result
    return self.__get_result()
  File "/opt/conda/lib/python3.8/concurrent/futures/_base.py", line 388, in __get_result
    raise self._exception
  File "/opt/conda/lib/python3.8/concurrent/futures/_base.py", line 328, in _invoke_callbacks
    callback(self)
  File "/opt/conda/lib/python3.8/site-packages/nipype/pipeline/plugins/multiproc.py", line 159, in _async_callback
    result = args.result()
  File "/opt/conda/lib/python3.8/concurrent/futures/_base.py", line 432, in result
    return self.__get_result()
  File "/opt/conda/lib/python3.8/concurrent/futures/_base.py", line 388, in __get_result
    raise self._exception
  File "/opt/conda/lib/python3.8/concurrent/futures/_base.py", line 328, in _invoke_callbacks
    callback(self)
  File "/opt/conda/lib/python3.8/site-packages/nipype/pipeline/plugins/multiproc.py", line 159, in _async_callback
    result = args.result()
  File "/opt/conda/lib/python3.8/concurrent/futures/_base.py", line 432, in result
    return self.__get_result()
  File "/opt/conda/lib/python3.8/concurrent/futures/_base.py", line 388, in __get_result
    raise self._exception
  File "/opt/conda/lib/python3.8/concurrent/futures/_base.py", line 328, in _invoke_callbacks
    callback(self)
  File "/opt/conda/lib/python3.8/site-packages/nipype/pipeline/plugins/multiproc.py", line 159, in _async_callback
    result = args.result()
  File "/opt/conda/lib/python3.8/concurrent/futures/_base.py", line 432, in result
    return self.__get_result()
  File "/opt/conda/lib/python3.8/concurrent/futures/_base.py", line 388, in __get_result
    raise self._exception
  File "/opt/conda/lib/python3.8/concurrent/futures/_base.py", line 328, in _invoke_callbacks
    callback(self)
  File "/opt/conda/lib/python3.8/site-packages/nipype/pipeline/plugins/multiproc.py", line 159, in _async_callback
    result = args.result()
  File "/opt/conda/lib/python3.8/concurrent/futures/_base.py", line 432, in result
    return self.__get_result()
  File "/opt/conda/lib/python3.8/concurrent/futures/_base.py", line 388, in __get_result
    raise self._exception
concurrent.futures.process.BrokenProcessPool: A process in the process pool was terminated abruptly while the future was running or pending.
exception calling callback for <Future at 0x2b8b99eae430 state=finished raised BrokenProcessPool>
Traceback (most recent call last):
  File "/opt/conda/lib/python3.8/concurrent/futures/_base.py", line 328, in _invoke_callbacks
    callback(self)
  File "/opt/conda/lib/python3.8/site-packages/nipype/pipeline/plugins/multiproc.py", line 159, in _async_callback
    result = args.result()
  File "/opt/conda/lib/python3.8/concurrent/futures/_base.py", line 432, in result
    return self.__get_result()
  File "/opt/conda/lib/python3.8/concurrent/futures/_base.py", line 388, in __get_result
    raise self._exception
  File "/opt/conda/lib/python3.8/concurrent/futures/_base.py", line 328, in _invoke_callbacks
    callback(self)
  File "/opt/conda/lib/python3.8/site-packages/nipype/pipeline/plugins/multiproc.py", line 159, in _async_callback
    result = args.result()
  File "/opt/conda/lib/python3.8/concurrent/futures/_base.py", line 432, in result
    return self.__get_result()
  File "/opt/conda/lib/python3.8/concurrent/futures/_base.py", line 388, in __get_result
    raise self._exception
  File "/opt/conda/lib/python3.8/concurrent/futures/_base.py", line 328, in _invoke_callbacks
    callback(self)
  File "/opt/conda/lib/python3.8/site-packages/nipype/pipeline/plugins/multiproc.py", line 159, in _async_callback
    result = args.result()
  File "/opt/conda/lib/python3.8/concurrent/futures/_base.py", line 432, in result
    return self.__get_result()
  File "/opt/conda/lib/python3.8/concurrent/futures/_base.py", line 388, in __get_result
    raise self._exception
  File "/opt/conda/lib/python3.8/concurrent/futures/_base.py", line 328, in _invoke_callbacks
    callback(self)
  File "/opt/conda/lib/python3.8/site-packages/nipype/pipeline/plugins/multiproc.py", line 159, in _async_callback
    result = args.result()
  File "/opt/conda/lib/python3.8/concurrent/futures/_base.py", line 432, in result
    return self.__get_result()
  File "/opt/conda/lib/python3.8/concurrent/futures/_base.py", line 388, in __get_result
    raise self._exception
  File "/opt/conda/lib/python3.8/concurrent/futures/_base.py", line 328, in _invoke_callbacks
    callback(self)
  File "/opt/conda/lib/python3.8/site-packages/nipype/pipeline/plugins/multiproc.py", line 159, in _async_callback
    result = args.result()
  File "/opt/conda/lib/python3.8/concurrent/futures/_base.py", line 432, in result
    return self.__get_result()
  File "/opt/conda/lib/python3.8/concurrent/futures/_base.py", line 388, in __get_result
    raise self._exception
  File "/opt/conda/lib/python3.8/concurrent/futures/_base.py", line 328, in _invoke_callbacks
    callback(self)
  File "/opt/conda/lib/python3.8/site-packages/nipype/pipeline/plugins/multiproc.py", line 159, in _async_callback
    result = args.result()
  File "/opt/conda/lib/python3.8/concurrent/futures/_base.py", line 432, in result
    return self.__get_result()
  File "/opt/conda/lib/python3.8/concurrent/futures/_base.py", line 388, in __get_result
    raise self._exception
  File "/opt/conda/lib/python3.8/concurrent/futures/_base.py", line 328, in _invoke_callbacks
    callback(self)
  File "/opt/conda/lib/python3.8/site-packages/nipype/pipeline/plugins/multiproc.py", line 159, in _async_callback
    result = args.result()
  File "/opt/conda/lib/python3.8/concurrent/futures/_base.py", line 432, in result
    return self.__get_result()
  File "/opt/conda/lib/python3.8/concurrent/futures/_base.py", line 388, in __get_result
    raise self._exception
  File "/opt/conda/lib/python3.8/concurrent/futures/_base.py", line 328, in _invoke_callbacks
    callback(self)
  File "/opt/conda/lib/python3.8/site-packages/nipype/pipeline/plugins/multiproc.py", line 159, in _async_callback
    result = args.result()
  File "/opt/conda/lib/python3.8/concurrent/futures/_base.py", line 432, in result
    return self.__get_result()
  File "/opt/conda/lib/python3.8/concurrent/futures/_base.py", line 388, in __get_result
    raise self._exception
  File "/opt/conda/lib/python3.8/concurrent/futures/_base.py", line 328, in _invoke_callbacks
    callback(self)
  File "/opt/conda/lib/python3.8/site-packages/nipype/pipeline/plugins/multiproc.py", line 159, in _async_callback
    result = args.result()
  File "/opt/conda/lib/python3.8/concurrent/futures/_base.py", line 432, in result
    return self.__get_result()
  File "/opt/conda/lib/python3.8/concurrent/futures/_base.py", line 388, in __get_result
    raise self._exception
  File "/opt/conda/lib/python3.8/concurrent/futures/_base.py", line 328, in _invoke_callbacks
    callback(self)
  File "/opt/conda/lib/python3.8/site-packages/nipype/pipeline/plugins/multiproc.py", line 159, in _async_callback
    result = args.result()
  File "/opt/conda/lib/python3.8/concurrent/futures/_base.py", line 432, in result
    return self.__get_result()
  File "/opt/conda/lib/python3.8/concurrent/futures/_base.py", line 388, in __get_result
    raise self._exception
  File "/opt/conda/lib/python3.8/concurrent/futures/_base.py", line 328, in _invoke_callbacks
    callback(self)
  File "/opt/conda/lib/python3.8/site-packages/nipype/pipeline/plugins/multiproc.py", line 159, in _async_callback
    result = args.result()
  File "/opt/conda/lib/python3.8/concurrent/futures/_base.py", line 432, in result
    return self.__get_result()
  File "/opt/conda/lib/python3.8/concurrent/futures/_base.py", line 388, in __get_result
    raise self._exception
concurrent.futures.process.BrokenProcessPool: A process in the process pool was terminated abruptly while the future was running or pending.
exception calling callback for <Future at 0x2b8b9fb3f490 state=finished raised BrokenProcessPool>
Traceback (most recent call last):
  File "/opt/conda/lib/python3.8/concurrent/futures/_base.py", line 328, in _invoke_callbacks
    callback(self)
  File "/opt/conda/lib/python3.8/site-packages/nipype/pipeline/plugins/multiproc.py", line 159, in _async_callback
    result = args.result()
  File "/opt/conda/lib/python3.8/concurrent/futures/_base.py", line 432, in result
    return self.__get_result()
  File "/opt/conda/lib/python3.8/concurrent/futures/_base.py", line 388, in __get_result
    raise self._exception
  File "/opt/conda/lib/python3.8/concurrent/futures/_base.py", line 328, in _invoke_callbacks
    callback(self)
  File "/opt/conda/lib/python3.8/site-packages/nipype/pipeline/plugins/multiproc.py", line 159, in _async_callback
    result = args.result()
  File "/opt/conda/lib/python3.8/concurrent/futures/_base.py", line 432, in result
    return self.__get_result()
  File "/opt/conda/lib/python3.8/concurrent/futures/_base.py", line 388, in __get_result
    raise self._exception
  File "/opt/conda/lib/python3.8/concurrent/futures/_base.py", line 328, in _invoke_callbacks
    callback(self)
  File "/opt/conda/lib/python3.8/site-packages/nipype/pipeline/plugins/multiproc.py", line 159, in _async_callback
    result = args.result()
  File "/opt/conda/lib/python3.8/concurrent/futures/_base.py", line 432, in result
    return self.__get_result()
  File "/opt/conda/lib/python3.8/concurrent/futures/_base.py", line 388, in __get_result
    raise self._exception
  File "/opt/conda/lib/python3.8/concurrent/futures/_base.py", line 328, in _invoke_callbacks
    callback(self)
  File "/opt/conda/lib/python3.8/site-packages/nipype/pipeline/plugins/multiproc.py", line 159, in _async_callback
    result = args.result()
  File "/opt/conda/lib/python3.8/concurrent/futures/_base.py", line 432, in result
    return self.__get_result()
  File "/opt/conda/lib/python3.8/concurrent/futures/_base.py", line 388, in __get_result
    raise self._exception
  File "/opt/conda/lib/python3.8/concurrent/futures/_base.py", line 328, in _invoke_callbacks
    callback(self)
  File "/opt/conda/lib/python3.8/site-packages/nipype/pipeline/plugins/multiproc.py", line 159, in _async_callback
    result = args.result()
  File "/opt/conda/lib/python3.8/concurrent/futures/_base.py", line 432, in result
    return self.__get_result()
  File "/opt/conda/lib/python3.8/concurrent/futures/_base.py", line 388, in __get_result
    raise self._exception
  File "/opt/conda/lib/python3.8/concurrent/futures/_base.py", line 328, in _invoke_callbacks
    callback(self)
  File "/opt/conda/lib/python3.8/site-packages/nipype/pipeline/plugins/multiproc.py", line 159, in _async_callback
    result = args.result()
  File "/opt/conda/lib/python3.8/concurrent/futures/_base.py", line 432, in result
    return self.__get_result()
  File "/opt/conda/lib/python3.8/concurrent/futures/_base.py", line 388, in __get_result
    raise self._exception
  File "/opt/conda/lib/python3.8/concurrent/futures/_base.py", line 328, in _invoke_callbacks
    callback(self)
  File "/opt/conda/lib/python3.8/site-packages/nipype/pipeline/plugins/multiproc.py", line 159, in _async_callback
    result = args.result()
  File "/opt/conda/lib/python3.8/concurrent/futures/_base.py", line 432, in result
    return self.__get_result()
  File "/opt/conda/lib/python3.8/concurrent/futures/_base.py", line 388, in __get_result
    raise self._exception
  File "/opt/conda/lib/python3.8/concurrent/futures/_base.py", line 328, in _invoke_callbacks
    callback(self)
  File "/opt/conda/lib/python3.8/site-packages/nipype/pipeline/plugins/multiproc.py", line 159, in _async_callback
    result = args.result()
  File "/opt/conda/lib/python3.8/concurrent/futures/_base.py", line 432, in result
    return self.__get_result()
  File "/opt/conda/lib/python3.8/concurrent/futures/_base.py", line 388, in __get_result
    raise self._exception
  File "/opt/conda/lib/python3.8/concurrent/futures/_base.py", line 328, in _invoke_callbacks
    callback(self)
  File "/opt/conda/lib/python3.8/site-packages/nipype/pipeline/plugins/multiproc.py", line 159, in _async_callback
    result = args.result()
  File "/opt/conda/lib/python3.8/concurrent/futures/_base.py", line 432, in result
    return self.__get_result()
  File "/opt/conda/lib/python3.8/concurrent/futures/_base.py", line 388, in __get_result
    raise self._exception
  File "/opt/conda/lib/python3.8/concurrent/futures/_base.py", line 328, in _invoke_callbacks
    callback(self)
  File "/opt/conda/lib/python3.8/site-packages/nipype/pipeline/plugins/multiproc.py", line 159, in _async_callback
    result = args.result()
  File "/opt/conda/lib/python3.8/concurrent/futures/_base.py", line 432, in result
    return self.__get_result()
  File "/opt/conda/lib/python3.8/concurrent/futures/_base.py", line 388, in __get_result
    raise self._exception
  File "/opt/conda/lib/python3.8/concurrent/futures/_base.py", line 328, in _invoke_callbacks
    callback(self)
  File "/opt/conda/lib/python3.8/site-packages/nipype/pipeline/plugins/multiproc.py", line 159, in _async_callback
    result = args.result()
  File "/opt/conda/lib/python3.8/concurrent/futures/_base.py", line 432, in result
    return self.__get_result()
  File "/opt/conda/lib/python3.8/concurrent/futures/_base.py", line 388, in __get_result
    raise self._exception
  File "/opt/conda/lib/python3.8/concurrent/futures/_base.py", line 328, in _invoke_callbacks
    callback(self)
  File "/opt/conda/lib/python3.8/site-packages/nipype/pipeline/plugins/multiproc.py", line 159, in _async_callback
    result = args.result()
  File "/opt/conda/lib/python3.8/concurrent/futures/_base.py", line 432, in result
    return self.__get_result()
  File "/opt/conda/lib/python3.8/concurrent/futures/_base.py", line 388, in __get_result
    raise self._exception
concurrent.futures.process.BrokenProcessPool: A process in the process pool was terminated abruptly while the future was running or pending.
exception calling callback for <Future at 0x2b8b99eae370 state=finished raised BrokenProcessPool>
Traceback (most recent call last):
  File "/opt/conda/lib/python3.8/concurrent/futures/_base.py", line 328, in _invoke_callbacks
    callback(self)
  File "/opt/conda/lib/python3.8/site-packages/nipype/pipeline/plugins/multiproc.py", line 159, in _async_callback
    result = args.result()
  File "/opt/conda/lib/python3.8/concurrent/futures/_base.py", line 432, in result
    return self.__get_result()
  File "/opt/conda/lib/python3.8/concurrent/futures/_base.py", line 388, in __get_result
    raise self._exception
  File "/opt/conda/lib/python3.8/concurrent/futures/_base.py", line 328, in _invoke_callbacks
    callback(self)
  File "/opt/conda/lib/python3.8/site-packages/nipype/pipeline/plugins/multiproc.py", line 159, in _async_callback
    result = args.result()
  File "/opt/conda/lib/python3.8/concurrent/futures/_base.py", line 432, in result
    return self.__get_result()
  File "/opt/conda/lib/python3.8/concurrent/futures/_base.py", line 388, in __get_result
    raise self._exception
  File "/opt/conda/lib/python3.8/concurrent/futures/_base.py", line 328, in _invoke_callbacks
    callback(self)
  File "/opt/conda/lib/python3.8/site-packages/nipype/pipeline/plugins/multiproc.py", line 159, in _async_callback
    result = args.result()
  File "/opt/conda/lib/python3.8/concurrent/futures/_base.py", line 432, in result
    return self.__get_result()
  File "/opt/conda/lib/python3.8/concurrent/futures/_base.py", line 388, in __get_result
    raise self._exception
  File "/opt/conda/lib/python3.8/concurrent/futures/_base.py", line 328, in _invoke_callbacks
    callback(self)
  File "/opt/conda/lib/python3.8/site-packages/nipype/pipeline/plugins/multiproc.py", line 159, in _async_callback
    result = args.result()
  File "/opt/conda/lib/python3.8/concurrent/futures/_base.py", line 432, in result
    return self.__get_result()
  File "/opt/conda/lib/python3.8/concurrent/futures/_base.py", line 388, in __get_result
    raise self._exception
  File "/opt/conda/lib/python3.8/concurrent/futures/_base.py", line 328, in _invoke_callbacks
    callback(self)
  File "/opt/conda/lib/python3.8/site-packages/nipype/pipeline/plugins/multiproc.py", line 159, in _async_callback
    result = args.result()
  File "/opt/conda/lib/python3.8/concurrent/futures/_base.py", line 432, in result
    return self.__get_result()
  File "/opt/conda/lib/python3.8/concurrent/futures/_base.py", line 388, in __get_result
    raise self._exception
  File "/opt/conda/lib/python3.8/concurrent/futures/_base.py", line 328, in _invoke_callbacks
    callback(self)
  File "/opt/conda/lib/python3.8/site-packages/nipype/pipeline/plugins/multiproc.py", line 159, in _async_callback
    result = args.result()
  File "/opt/conda/lib/python3.8/concurrent/futures/_base.py", line 432, in result
    return self.__get_result()
  File "/opt/conda/lib/python3.8/concurrent/futures/_base.py", line 388, in __get_result
    raise self._exception
  File "/opt/conda/lib/python3.8/concurrent/futures/_base.py", line 328, in _invoke_callbacks
    callback(self)
  File "/opt/conda/lib/python3.8/site-packages/nipype/pipeline/plugins/multiproc.py", line 159, in _async_callback
    result = args.result()
  File "/opt/conda/lib/python3.8/concurrent/futures/_base.py", line 432, in result
    return self.__get_result()
  File "/opt/conda/lib/python3.8/concurrent/futures/_base.py", line 388, in __get_result
    raise self._exception
  File "/opt/conda/lib/python3.8/concurrent/futures/_base.py", line 328, in _invoke_callbacks
    callback(self)
  File "/opt/conda/lib/python3.8/site-packages/nipype/pipeline/plugins/multiproc.py", line 159, in _async_callback
    result = args.result()
  File "/opt/conda/lib/python3.8/concurrent/futures/_base.py", line 432, in result
    return self.__get_result()
  File "/opt/conda/lib/python3.8/concurrent/futures/_base.py", line 388, in __get_result
    raise self._exception
  File "/opt/conda/lib/python3.8/concurrent/futures/_base.py", line 328, in _invoke_callbacks
    callback(self)
  File "/opt/conda/lib/python3.8/site-packages/nipype/pipeline/plugins/multiproc.py", line 159, in _async_callback
    result = args.result()
  File "/opt/conda/lib/python3.8/concurrent/futures/_base.py", line 432, in result
    return self.__get_result()
  File "/opt/conda/lib/python3.8/concurrent/futures/_base.py", line 388, in __get_result
    raise self._exception
  File "/opt/conda/lib/python3.8/concurrent/futures/_base.py", line 328, in _invoke_callbacks
    callback(self)
  File "/opt/conda/lib/python3.8/site-packages/nipype/pipeline/plugins/multiproc.py", line 159, in _async_callback
    result = args.result()
  File "/opt/conda/lib/python3.8/concurrent/futures/_base.py", line 432, in result
    return self.__get_result()
  File "/opt/conda/lib/python3.8/concurrent/futures/_base.py", line 388, in __get_result
    raise self._exception
  File "/opt/conda/lib/python3.8/concurrent/futures/_base.py", line 328, in _invoke_callbacks
    callback(self)
  File "/opt/conda/lib/python3.8/site-packages/nipype/pipeline/plugins/multiproc.py", line 159, in _async_callback
    result = args.result()
  File "/opt/conda/lib/python3.8/concurrent/futures/_base.py", line 432, in result
    return self.__get_result()
  File "/opt/conda/lib/python3.8/concurrent/futures/_base.py", line 388, in __get_result
    raise self._exception
  File "/opt/conda/lib/python3.8/concurrent/futures/_base.py", line 328, in _invoke_callbacks
    callback(self)
  File "/opt/conda/lib/python3.8/site-packages/nipype/pipeline/plugins/multiproc.py", line 159, in _async_callback
    result = args.result()
  File "/opt/conda/lib/python3.8/concurrent/futures/_base.py", line 432, in result
    return self.__get_result()
  File "/opt/conda/lib/python3.8/concurrent/futures/_base.py", line 388, in __get_result
    raise self._exception
  File "/opt/conda/lib/python3.8/concurrent/futures/_base.py", line 328, in _invoke_callbacks
    callback(self)
  File "/opt/conda/lib/python3.8/site-packages/nipype/pipeline/plugins/multiproc.py", line 159, in _async_callback
    result = args.result()
  File "/opt/conda/lib/python3.8/concurrent/futures/_base.py", line 432, in result
    return self.__get_result()
  File "/opt/conda/lib/python3.8/concurrent/futures/_base.py", line 388, in __get_result
    raise self._exception
concurrent.futures.process.BrokenProcessPool: A process in the process pool was terminated abruptly while the future was running or pending.
exception calling callback for <Future at 0x2b8ba17a5100 state=finished raised BrokenProcessPool>
Traceback (most recent call last):
  File "/opt/conda/lib/python3.8/concurrent/futures/_base.py", line 328, in _invoke_callbacks
    callback(self)
  File "/opt/conda/lib/python3.8/site-packages/nipype/pipeline/plugins/multiproc.py", line 159, in _async_callback
    result = args.result()
  File "/opt/conda/lib/python3.8/concurrent/futures/_base.py", line 432, in result
    return self.__get_result()
  File "/opt/conda/lib/python3.8/concurrent/futures/_base.py", line 388, in __get_result
    raise self._exception
  File "/opt/conda/lib/python3.8/concurrent/futures/_base.py", line 328, in _invoke_callbacks
    callback(self)
  File "/opt/conda/lib/python3.8/site-packages/nipype/pipeline/plugins/multiproc.py", line 159, in _async_callback
    result = args.result()
  File "/opt/conda/lib/python3.8/concurrent/futures/_base.py", line 432, in result
    return self.__get_result()
  File "/opt/conda/lib/python3.8/concurrent/futures/_base.py", line 388, in __get_result
    raise self._exception
  File "/opt/conda/lib/python3.8/concurrent/futures/_base.py", line 328, in _invoke_callbacks
    callback(self)
  File "/opt/conda/lib/python3.8/site-packages/nipype/pipeline/plugins/multiproc.py", line 159, in _async_callback
    result = args.result()
  File "/opt/conda/lib/python3.8/concurrent/futures/_base.py", line 432, in result
    return self.__get_result()
  File "/opt/conda/lib/python3.8/concurrent/futures/_base.py", line 388, in __get_result
    raise self._exception
  File "/opt/conda/lib/python3.8/concurrent/futures/_base.py", line 328, in _invoke_callbacks
    callback(self)
  File "/opt/conda/lib/python3.8/site-packages/nipype/pipeline/plugins/multiproc.py", line 159, in _async_callback
    result = args.result()
  File "/opt/conda/lib/python3.8/concurrent/futures/_base.py", line 432, in result
    return self.__get_result()
  File "/opt/conda/lib/python3.8/concurrent/futures/_base.py", line 388, in __get_result
    raise self._exception
  File "/opt/conda/lib/python3.8/concurrent/futures/_base.py", line 328, in _invoke_callbacks
    callback(self)
  File "/opt/conda/lib/python3.8/site-packages/nipype/pipeline/plugins/multiproc.py", line 159, in _async_callback
    result = args.result()
  File "/opt/conda/lib/python3.8/concurrent/futures/_base.py", line 432, in result
    return self.__get_result()
  File "/opt/conda/lib/python3.8/concurrent/futures/_base.py", line 388, in __get_result
    raise self._exception
  File "/opt/conda/lib/python3.8/concurrent/futures/_base.py", line 328, in _invoke_callbacks
    callback(self)
  File "/opt/conda/lib/python3.8/site-packages/nipype/pipeline/plugins/multiproc.py", line 159, in _async_callback
    result = args.result()
  File "/opt/conda/lib/python3.8/concurrent/futures/_base.py", line 432, in result
    return self.__get_result()
  File "/opt/conda/lib/python3.8/concurrent/futures/_base.py", line 388, in __get_result
    raise self._exception
  File "/opt/conda/lib/python3.8/concurrent/futures/_base.py", line 328, in _invoke_callbacks
    callback(self)
  File "/opt/conda/lib/python3.8/site-packages/nipype/pipeline/plugins/multiproc.py", line 159, in _async_callback
    result = args.result()
  File "/opt/conda/lib/python3.8/concurrent/futures/_base.py", line 432, in result
    return self.__get_result()
  File "/opt/conda/lib/python3.8/concurrent/futures/_base.py", line 388, in __get_result
    raise self._exception
  File "/opt/conda/lib/python3.8/concurrent/futures/_base.py", line 328, in _invoke_callbacks
    callback(self)
  File "/opt/conda/lib/python3.8/site-packages/nipype/pipeline/plugins/multiproc.py", line 159, in _async_callback
    result = args.result()
  File "/opt/conda/lib/python3.8/concurrent/futures/_base.py", line 432, in result
    return self.__get_result()
  File "/opt/conda/lib/python3.8/concurrent/futures/_base.py", line 388, in __get_result
    raise self._exception
  File "/opt/conda/lib/python3.8/concurrent/futures/_base.py", line 328, in _invoke_callbacks
    callback(self)
  File "/opt/conda/lib/python3.8/site-packages/nipype/pipeline/plugins/multiproc.py", line 159, in _async_callback
    result = args.result()
  File "/opt/conda/lib/python3.8/concurrent/futures/_base.py", line 432, in result
    return self.__get_result()
  File "/opt/conda/lib/python3.8/concurrent/futures/_base.py", line 388, in __get_result
    raise self._exception
  File "/opt/conda/lib/python3.8/concurrent/futures/_base.py", line 328, in _invoke_callbacks
    callback(self)
  File "/opt/conda/lib/python3.8/site-packages/nipype/pipeline/plugins/multiproc.py", line 159, in _async_callback
    result = args.result()
  File "/opt/conda/lib/python3.8/concurrent/futures/_base.py", line 432, in result
    return self.__get_result()
  File "/opt/conda/lib/python3.8/concurrent/futures/_base.py", line 388, in __get_result
    raise self._exception
  File "/opt/conda/lib/python3.8/concurrent/futures/_base.py", line 328, in _invoke_callbacks
    callback(self)
  File "/opt/conda/lib/python3.8/site-packages/nipype/pipeline/plugins/multiproc.py", line 159, in _async_callback
    result = args.result()
  File "/opt/conda/lib/python3.8/concurrent/futures/_base.py", line 432, in result
    return self.__get_result()
  File "/opt/conda/lib/python3.8/concurrent/futures/_base.py", line 388, in __get_result
    raise self._exception
  File "/opt/conda/lib/python3.8/concurrent/futures/_base.py", line 328, in _invoke_callbacks
    callback(self)
  File "/opt/conda/lib/python3.8/site-packages/nipype/pipeline/plugins/multiproc.py", line 159, in _async_callback
    result = args.result()
  File "/opt/conda/lib/python3.8/concurrent/futures/_base.py", line 432, in result
    return self.__get_result()
  File "/opt/conda/lib/python3.8/concurrent/futures/_base.py", line 388, in __get_result
    raise self._exception
  File "/opt/conda/lib/python3.8/concurrent/futures/_base.py", line 328, in _invoke_callbacks
    callback(self)
  File "/opt/conda/lib/python3.8/site-packages/nipype/pipeline/plugins/multiproc.py", line 159, in _async_callback
    result = args.result()
  File "/opt/conda/lib/python3.8/concurrent/futures/_base.py", line 432, in result
    return self.__get_result()
  File "/opt/conda/lib/python3.8/concurrent/futures/_base.py", line 388, in __get_result
    raise self._exception
  File "/opt/conda/lib/python3.8/concurrent/futures/_base.py", line 328, in _invoke_callbacks
    callback(self)
  File "/opt/conda/lib/python3.8/site-packages/nipype/pipeline/plugins/multiproc.py", line 159, in _async_callback
    result = args.result()
  File "/opt/conda/lib/python3.8/concurrent/futures/_base.py", line 432, in result
    return self.__get_result()
  File "/opt/conda/lib/python3.8/concurrent/futures/_base.py", line 388, in __get_result
    raise self._exception
concurrent.futures.process.BrokenProcessPool: A process in the process pool was terminated abruptly while the future was running or pending.
exception calling callback for <Future at 0x2b8ba17a5730 state=finished raised BrokenProcessPool>
Traceback (most recent call last):
  File "/opt/conda/lib/python3.8/concurrent/futures/_base.py", line 328, in _invoke_callbacks
    callback(self)
  File "/opt/conda/lib/python3.8/site-packages/nipype/pipeline/plugins/multiproc.py", line 159, in _async_callback
    result = args.result()
  File "/opt/conda/lib/python3.8/concurrent/futures/_base.py", line 432, in result
    return self.__get_result()
  File "/opt/conda/lib/python3.8/concurrent/futures/_base.py", line 388, in __get_result
    raise self._exception
  File "/opt/conda/lib/python3.8/concurrent/futures/_base.py", line 328, in _invoke_callbacks
    callback(self)
  File "/opt/conda/lib/python3.8/site-packages/nipype/pipeline/plugins/multiproc.py", line 159, in _async_callback
    result = args.result()
  File "/opt/conda/lib/python3.8/concurrent/futures/_base.py", line 432, in result
    return self.__get_result()
  File "/opt/conda/lib/python3.8/concurrent/futures/_base.py", line 388, in __get_result
    raise self._exception
  File "/opt/conda/lib/python3.8/concurrent/futures/_base.py", line 328, in _invoke_callbacks
    callback(self)
  File "/opt/conda/lib/python3.8/site-packages/nipype/pipeline/plugins/multiproc.py", line 159, in _async_callback
    result = args.result()
  File "/opt/conda/lib/python3.8/concurrent/futures/_base.py", line 432, in result
    return self.__get_result()
  File "/opt/conda/lib/python3.8/concurrent/futures/_base.py", line 388, in __get_result
    raise self._exception
  File "/opt/conda/lib/python3.8/concurrent/futures/_base.py", line 328, in _invoke_callbacks
    callback(self)
  File "/opt/conda/lib/python3.8/site-packages/nipype/pipeline/plugins/multiproc.py", line 159, in _async_callback
    result = args.result()
  File "/opt/conda/lib/python3.8/concurrent/futures/_base.py", line 432, in result
    return self.__get_result()
  File "/opt/conda/lib/python3.8/concurrent/futures/_base.py", line 388, in __get_result
    raise self._exception
  File "/opt/conda/lib/python3.8/concurrent/futures/_base.py", line 328, in _invoke_callbacks
    callback(self)
  File "/opt/conda/lib/python3.8/site-packages/nipype/pipeline/plugins/multiproc.py", line 159, in _async_callback
    result = args.result()
  File "/opt/conda/lib/python3.8/concurrent/futures/_base.py", line 432, in result
    return self.__get_result()
  File "/opt/conda/lib/python3.8/concurrent/futures/_base.py", line 388, in __get_result
    raise self._exception
  File "/opt/conda/lib/python3.8/concurrent/futures/_base.py", line 328, in _invoke_callbacks
    callback(self)
  File "/opt/conda/lib/python3.8/site-packages/nipype/pipeline/plugins/multiproc.py", line 159, in _async_callback
    result = args.result()
  File "/opt/conda/lib/python3.8/concurrent/futures/_base.py", line 432, in result
    return self.__get_result()
  File "/opt/conda/lib/python3.8/concurrent/futures/_base.py", line 388, in __get_result
    raise self._exception
  File "/opt/conda/lib/python3.8/concurrent/futures/_base.py", line 328, in _invoke_callbacks
    callback(self)
  File "/opt/conda/lib/python3.8/site-packages/nipype/pipeline/plugins/multiproc.py", line 159, in _async_callback
    result = args.result()
  File "/opt/conda/lib/python3.8/concurrent/futures/_base.py", line 432, in result
    return self.__get_result()
  File "/opt/conda/lib/python3.8/concurrent/futures/_base.py", line 388, in __get_result
    raise self._exception
  File "/opt/conda/lib/python3.8/concurrent/futures/_base.py", line 328, in _invoke_callbacks
    callback(self)
  File "/opt/conda/lib/python3.8/site-packages/nipype/pipeline/plugins/multiproc.py", line 159, in _async_callback
    result = args.result()
  File "/opt/conda/lib/python3.8/concurrent/futures/_base.py", line 432, in result
    return self.__get_result()
  File "/opt/conda/lib/python3.8/concurrent/futures/_base.py", line 388, in __get_result
    raise self._exception
  File "/opt/conda/lib/python3.8/concurrent/futures/_base.py", line 328, in _invoke_callbacks
    callback(self)
  File "/opt/conda/lib/python3.8/site-packages/nipype/pipeline/plugins/multiproc.py", line 159, in _async_callback
    result = args.result()
  File "/opt/conda/lib/python3.8/concurrent/futures/_base.py", line 432, in result
    return self.__get_result()
  File "/opt/conda/lib/python3.8/concurrent/futures/_base.py", line 388, in __get_result
    raise self._exception
  File "/opt/conda/lib/python3.8/concurrent/futures/_base.py", line 328, in _invoke_callbacks
    callback(self)
  File "/opt/conda/lib/python3.8/site-packages/nipype/pipeline/plugins/multiproc.py", line 159, in _async_callback
    result = args.result()
  File "/opt/conda/lib/python3.8/concurrent/futures/_base.py", line 432, in result
    return self.__get_result()
  File "/opt/conda/lib/python3.8/concurrent/futures/_base.py", line 388, in __get_result
    raise self._exception
  File "/opt/conda/lib/python3.8/concurrent/futures/_base.py", line 328, in _invoke_callbacks
    callback(self)
  File "/opt/conda/lib/python3.8/site-packages/nipype/pipeline/plugins/multiproc.py", line 159, in _async_callback
    result = args.result()
  File "/opt/conda/lib/python3.8/concurrent/futures/_base.py", line 432, in result
    return self.__get_result()
  File "/opt/conda/lib/python3.8/concurrent/futures/_base.py", line 388, in __get_result
    raise self._exception
  File "/opt/conda/lib/python3.8/concurrent/futures/_base.py", line 328, in _invoke_callbacks
    callback(self)
  File "/opt/conda/lib/python3.8/site-packages/nipype/pipeline/plugins/multiproc.py", line 159, in _async_callback
    result = args.result()
  File "/opt/conda/lib/python3.8/concurrent/futures/_base.py", line 432, in result
    return self.__get_result()
  File "/opt/conda/lib/python3.8/concurrent/futures/_base.py", line 388, in __get_result
    raise self._exception
  File "/opt/conda/lib/python3.8/concurrent/futures/_base.py", line 328, in _invoke_callbacks
    callback(self)
  File "/opt/conda/lib/python3.8/site-packages/nipype/pipeline/plugins/multiproc.py", line 159, in _async_callback
    result = args.result()
  File "/opt/conda/lib/python3.8/concurrent/futures/_base.py", line 432, in result
    return self.__get_result()
  File "/opt/conda/lib/python3.8/concurrent/futures/_base.py", line 388, in __get_result
    raise self._exception
  File "/opt/conda/lib/python3.8/concurrent/futures/_base.py", line 328, in _invoke_callbacks
    callback(self)
  File "/opt/conda/lib/python3.8/site-packages/nipype/pipeline/plugins/multiproc.py", line 159, in _async_callback
    result = args.result()
  File "/opt/conda/lib/python3.8/concurrent/futures/_base.py", line 432, in result
    return self.__get_result()
  File "/opt/conda/lib/python3.8/concurrent/futures/_base.py", line 388, in __get_result
    raise self._exception
  File "/opt/conda/lib/python3.8/concurrent/futures/_base.py", line 328, in _invoke_callbacks
    callback(self)
  File "/opt/conda/lib/python3.8/site-packages/nipype/pipeline/plugins/multiproc.py", line 159, in _async_callback
    result = args.result()
  File "/opt/conda/lib/python3.8/concurrent/futures/_base.py", line 432, in result
    return self.__get_result()
  File "/opt/conda/lib/python3.8/concurrent/futures/_base.py", line 388, in __get_result
    raise self._exception
concurrent.futures.process.BrokenProcessPool: A process in the process pool was terminated abruptly while the future was running or pending.
exception calling callback for <Future at 0x2b8ba17a5160 state=finished raised BrokenProcessPool>
Traceback (most recent call last):
  File "/opt/conda/lib/python3.8/concurrent/futures/_base.py", line 328, in _invoke_callbacks
    callback(self)
  File "/opt/conda/lib/python3.8/site-packages/nipype/pipeline/plugins/multiproc.py", line 159, in _async_callback
    result = args.result()
  File "/opt/conda/lib/python3.8/concurrent/futures/_base.py", line 432, in result
    return self.__get_result()
  File "/opt/conda/lib/python3.8/concurrent/futures/_base.py", line 388, in __get_result
    raise self._exception
  File "/opt/conda/lib/python3.8/concurrent/futures/_base.py", line 328, in _invoke_callbacks
    callback(self)
  File "/opt/conda/lib/python3.8/site-packages/nipype/pipeline/plugins/multiproc.py", line 159, in _async_callback
    result = args.result()
  File "/opt/conda/lib/python3.8/concurrent/futures/_base.py", line 432, in result
    return self.__get_result()
  File "/opt/conda/lib/python3.8/concurrent/futures/_base.py", line 388, in __get_result
    raise self._exception
  File "/opt/conda/lib/python3.8/concurrent/futures/_base.py", line 328, in _invoke_callbacks
    callback(self)
  File "/opt/conda/lib/python3.8/site-packages/nipype/pipeline/plugins/multiproc.py", line 159, in _async_callback
    result = args.result()
  File "/opt/conda/lib/python3.8/concurrent/futures/_base.py", line 432, in result
    return self.__get_result()
  File "/opt/conda/lib/python3.8/concurrent/futures/_base.py", line 388, in __get_result
    raise self._exception
  File "/opt/conda/lib/python3.8/concurrent/futures/_base.py", line 328, in _invoke_callbacks
    callback(self)
  File "/opt/conda/lib/python3.8/site-packages/nipype/pipeline/plugins/multiproc.py", line 159, in _async_callback
    result = args.result()
  File "/opt/conda/lib/python3.8/concurrent/futures/_base.py", line 432, in result
    return self.__get_result()
  File "/opt/conda/lib/python3.8/concurrent/futures/_base.py", line 388, in __get_result
    raise self._exception
  File "/opt/conda/lib/python3.8/concurrent/futures/_base.py", line 328, in _invoke_callbacks
    callback(self)
  File "/opt/conda/lib/python3.8/site-packages/nipype/pipeline/plugins/multiproc.py", line 159, in _async_callback
    result = args.result()
  File "/opt/conda/lib/python3.8/concurrent/futures/_base.py", line 432, in result
    return self.__get_result()
  File "/opt/conda/lib/python3.8/concurrent/futures/_base.py", line 388, in __get_result
    raise self._exception
  File "/opt/conda/lib/python3.8/concurrent/futures/_base.py", line 328, in _invoke_callbacks
    callback(self)
  File "/opt/conda/lib/python3.8/site-packages/nipype/pipeline/plugins/multiproc.py", line 159, in _async_callback
    result = args.result()
  File "/opt/conda/lib/python3.8/concurrent/futures/_base.py", line 432, in result
    return self.__get_result()
  File "/opt/conda/lib/python3.8/concurrent/futures/_base.py", line 388, in __get_result
    raise self._exception
  File "/opt/conda/lib/python3.8/concurrent/futures/_base.py", line 328, in _invoke_callbacks
    callback(self)
  File "/opt/conda/lib/python3.8/site-packages/nipype/pipeline/plugins/multiproc.py", line 159, in _async_callback
    result = args.result()
  File "/opt/conda/lib/python3.8/concurrent/futures/_base.py", line 432, in result
    return self.__get_result()
  File "/opt/conda/lib/python3.8/concurrent/futures/_base.py", line 388, in __get_result
    raise self._exception
  File "/opt/conda/lib/python3.8/concurrent/futures/_base.py", line 328, in _invoke_callbacks
    callback(self)
  File "/opt/conda/lib/python3.8/site-packages/nipype/pipeline/plugins/multiproc.py", line 159, in _async_callback
    result = args.result()
  File "/opt/conda/lib/python3.8/concurrent/futures/_base.py", line 432, in result
    return self.__get_result()
  File "/opt/conda/lib/python3.8/concurrent/futures/_base.py", line 388, in __get_result
    raise self._exception
  File "/opt/conda/lib/python3.8/concurrent/futures/_base.py", line 328, in _invoke_callbacks
    callback(self)
  File "/opt/conda/lib/python3.8/site-packages/nipype/pipeline/plugins/multiproc.py", line 159, in _async_callback
    result = args.result()
  File "/opt/conda/lib/python3.8/concurrent/futures/_base.py", line 432, in result
    return self.__get_result()
  File "/opt/conda/lib/python3.8/concurrent/futures/_base.py", line 388, in __get_result
    raise self._exception
  File "/opt/conda/lib/python3.8/concurrent/futures/_base.py", line 328, in _invoke_callbacks
    callback(self)
  File "/opt/conda/lib/python3.8/site-packages/nipype/pipeline/plugins/multiproc.py", line 159, in _async_callback
    result = args.result()
  File "/opt/conda/lib/python3.8/concurrent/futures/_base.py", line 432, in result
    return self.__get_result()
  File "/opt/conda/lib/python3.8/concurrent/futures/_base.py", line 388, in __get_result
    raise self._exception
  File "/opt/conda/lib/python3.8/concurrent/futures/_base.py", line 328, in _invoke_callbacks
    callback(self)
  File "/opt/conda/lib/python3.8/site-packages/nipype/pipeline/plugins/multiproc.py", line 159, in _async_callback
    result = args.result()
  File "/opt/conda/lib/python3.8/concurrent/futures/_base.py", line 432, in result
    return self.__get_result()
  File "/opt/conda/lib/python3.8/concurrent/futures/_base.py", line 388, in __get_result
    raise self._exception
  File "/opt/conda/lib/python3.8/concurrent/futures/_base.py", line 328, in _invoke_callbacks
    callback(self)
  File "/opt/conda/lib/python3.8/site-packages/nipype/pipeline/plugins/multiproc.py", line 159, in _async_callback
    result = args.result()
  File "/opt/conda/lib/python3.8/concurrent/futures/_base.py", line 432, in result
    return self.__get_result()
  File "/opt/conda/lib/python3.8/concurrent/futures/_base.py", line 388, in __get_result
    raise self._exception
  File "/opt/conda/lib/python3.8/concurrent/futures/_base.py", line 328, in _invoke_callbacks
    callback(self)
  File "/opt/conda/lib/python3.8/site-packages/nipype/pipeline/plugins/multiproc.py", line 159, in _async_callback
    result = args.result()
  File "/opt/conda/lib/python3.8/concurrent/futures/_base.py", line 432, in result
    return self.__get_result()
  File "/opt/conda/lib/python3.8/concurrent/futures/_base.py", line 388, in __get_result
    raise self._exception
  File "/opt/conda/lib/python3.8/concurrent/futures/_base.py", line 328, in _invoke_callbacks
    callback(self)
  File "/opt/conda/lib/python3.8/site-packages/nipype/pipeline/plugins/multiproc.py", line 159, in _async_callback
    result = args.result()
  File "/opt/conda/lib/python3.8/concurrent/futures/_base.py", line 432, in result
    return self.__get_result()
  File "/opt/conda/lib/python3.8/concurrent/futures/_base.py", line 388, in __get_result
    raise self._exception
  File "/opt/conda/lib/python3.8/concurrent/futures/_base.py", line 328, in _invoke_callbacks
    callback(self)
  File "/opt/conda/lib/python3.8/site-packages/nipype/pipeline/plugins/multiproc.py", line 159, in _async_callback
    result = args.result()
  File "/opt/conda/lib/python3.8/concurrent/futures/_base.py", line 432, in result
    return self.__get_result()
  File "/opt/conda/lib/python3.8/concurrent/futures/_base.py", line 388, in __get_result
    raise self._exception
  File "/opt/conda/lib/python3.8/concurrent/futures/_base.py", line 328, in _invoke_callbacks
    callback(self)
  File "/opt/conda/lib/python3.8/site-packages/nipype/pipeline/plugins/multiproc.py", line 159, in _async_callback
    result = args.result()
  File "/opt/conda/lib/python3.8/concurrent/futures/_base.py", line 432, in result
    return self.__get_result()
  File "/opt/conda/lib/python3.8/concurrent/futures/_base.py", line 388, in __get_result
    raise self._exception
concurrent.futures.process.BrokenProcessPool: A process in the process pool was terminated abruptly while the future was running or pending.
Traceback (most recent call last):
  File "/opt/conda/bin/mriqc", line 8, in <module>
    sys.exit(main())
  File "/opt/conda/lib/python3.8/site-packages/mriqc/cli/run.py", line 95, in main
    mriqc_wf.run(**config.nipype.get_plugin())
  File "/opt/conda/lib/python3.8/site-packages/nipype/pipeline/engine/workflows.py", line 638, in run
    runner.run(execgraph, updatehash=updatehash, config=self.config)
  File "/opt/conda/lib/python3.8/site-packages/nipype/pipeline/plugins/base.py", line 164, in run
    self._clean_queue(jobid, graph, result=result)
  File "/opt/conda/lib/python3.8/site-packages/nipype/pipeline/plugins/base.py", line 227, in _clean_queue
    raise RuntimeError("".join(result["traceback"]))
RuntimeError: Traceback (most recent call last):
  File "/opt/conda/lib/python3.8/site-packages/nipype/pipeline/plugins/multiproc.py", line 67, in run_node
    result["result"] = node.run(updatehash=updatehash)
  File "/opt/conda/lib/python3.8/site-packages/nipype/pipeline/engine/nodes.py", line 516, in run
    result = self._run_interface(execute=True)
  File "/opt/conda/lib/python3.8/site-packages/nipype/pipeline/engine/nodes.py", line 635, in _run_interface
    return self._run_command(execute)
  File "/opt/conda/lib/python3.8/site-packages/nipype/pipeline/engine/nodes.py", line 741, in _run_command
    result = self._interface.run(cwd=outdir)
  File "/opt/conda/lib/python3.8/site-packages/nipype/interfaces/base/core.py", line 428, in run
    runtime = self._run_interface(runtime)
  File "/opt/conda/lib/python3.8/site-packages/mriqc/interfaces/anatomical.py", line 421, in _run_interface
    data = in_file.get_data()
  File "/opt/conda/lib/python3.8/site-packages/nibabel/deprecator.py", line 183, in deprecated_func
    return func(*args, **kwargs)
  File "/opt/conda/lib/python3.8/site-packages/nibabel/dataobj_images.py", line 207, in get_data
    data = np.asanyarray(self._dataobj)
  File "/opt/conda/lib/python3.8/site-packages/numpy/core/_asarray.py", line 171, in asanyarray
    return array(a, dtype, copy=False, order=order, subok=True)
  File "/opt/conda/lib/python3.8/site-packages/nibabel/arrayproxy.py", line 391, in __array__
    arr = self._get_scaled(dtype=dtype, slicer=())
  File "/opt/conda/lib/python3.8/site-packages/nibabel/arrayproxy.py", line 358, in _get_scaled
    scaled = apply_read_scaling(self._get_unscaled(slicer=slicer), scl_slope, scl_inter)
  File "/opt/conda/lib/python3.8/site-packages/nibabel/arrayproxy.py", line 332, in _get_unscaled
    return array_from_file(self._shape,
  File "/opt/conda/lib/python3.8/site-packages/nibabel/volumeutils.py", line 521, in array_from_file
    data_bytes = bytearray(n_bytes)
MemoryError

